Workbook

Sheet summary
K2: fuel station in 2017 :
A4: SN | B4: Date | C4: Bank | D4: fuel stations | E4: Description | K4: collection | L4: loaded | M4: difference
D5: Gesuba(Welaita) | I5: ='Gesuba(Welaita)'!K72 -> 52276377 | K5: ='Gesuba(Welaita)'!K46 -> 58777482 | L5: ='Gesuba(Welaita)'!K72 -> 52276377 | M5: =K5-L5 -> 6501104.6
D6: metu(Elibabora) | K6: ='Metu(Elibabora)'!K51 -> 60645926 | L6: ='Metu(Elibabora)'!K78 -> 54094781 | M6: =K6-L6 -> 6551145.4
D7: Leha(Gofa) | K7: ='Leha(Gofa)'!K51 -> 45813228 | L7: ='Leha(Gofa)'!K86 -> 33056293 | M7: =K7-L7 -> 12756935
D8: Mito(Silta) | K8: ='Mito(Silta)'!K51 -> 35921855 | L8: ='Mito(Silta)'!K86 -> 31502508 | M8: =K8-L8 -> 4419346.7
D9: Batu(Coustic) | K9: ='Batu(Coustic Soda)'!K51 -> 12238955 | L9: ='Batu(Coustic Soda)'!K86 -> 11814647 | M9: =K9-L9 -> 424307.49
D10: DashenGonder) | K10: ='Dashine(Gonder)'!K51 -> 34795274 | L10: ='Dashine(Gonder)'!K86 -> 26876010 | M10: =K10-L10 -> 7919264.6
D11: Dubti(Sordo) | K11: ='Dubti(Sordo)'!K47 -> 1400000 | L11: ='Dubti(Sordo)'!K85 -> 3722989.5 | M11: =K11-L11 -> -2322989.5
D12: S.Humera | K12: =S.Humera!K47 -> 7000000 | L12: =S.Humera!K85 -> 8574100.2 | M12: =K12-L12 -> -1574100.2
D13: Adebay | K13: =Adebay!K50 -> 8400000 | L13: =Adebay!K84 -> 8788545.2 | M13: =K13-L13 -> -388545.25
D14: Baeker | K14: =Baeker!K50 -> 25300000 | L14: =Baeker!K85 -> 20055678 | M14: =K14-L14 -> 5244321.9
D15: Dansha(Wendem) | K15: ='Dansha(Wendem)'!L47 -> 17821732 | L15: ='Dansha(Wendem)'!L86 -> 17294642 | M15: =K15-L15 -> 527089.99
D16: Gonder Bikl Factory | K16: ='Gonder Bikl Factory'!K50 -> 4281600 | L16: ='Gonder Bikl Factory'!K85 -> 3431987.8 | M16: =K16-L16 -> 849612.16
D17: total | K17: =SUM(K5:K16) -> 3.1239605e+08 | L17: =SUM(L5:L16) -> 2.7148856e+08 | M17: =SUM(M5:M16) -> 40907493

Sheet EpSE Report
D2: EPSE Balance Report | J2: Date | K2: 45481
A4: SN | B4: Date | C4: Bank | D4: Reference | E4: Receit No | F4: Description | K4: Amounts
D5: Transfer from last Year | K5: 7806062.2
E6: Advance paid to EPSE :
A7: 1 | B7: 10/07/24 | C7: CBE | E7: Advance paid to EPSE : | K7: 4000000
A8: 2 | B8: 10/07/24 | C8: CBE | E8: Advance paid to EPSE : | K8: 1000000
A9: 3 | B9: 45488 | C9: CBE | E9: Advance paid to EPSE : | K9: 500000
A10: 4 | B10: 45489 | C10: CBE | E10: Advance paid to EPSE : | K10: 500000
A11: 5 | B11: 45489 | C11: CBE | E11: Advance paid to EPSE : | K11: 2700000
A12: 6 | B12: 45490 | C12: CBE | E12: Advance paid to EPSE : | K12: 4500000
A13: 7 | B13: 45497 | C13: CBE | E13: Advance paid to EPSE : | K13: 2000000
A14: 8 | B14: 45497 | C14: Awash | E14: Advance paid to EPSE : | K14: 2000000
A15: 9 | B15: 45499 | C15: CBE | D15: FT242085B3FW | E15: Advance paid to EPSE : | K15: 4200000
A16: 10 | B16: 45499 | C16: CBE | D16: FT24208VYRZQ | E16: Advance paid to EPSE : | K16: 6000000
A17: 11 | B17: 45502 | C17: CBE | D17: FT24211QLPQR | E17: Advance paid to EPSE : | K17: 3200000
A18: 12 | B18: 45505 | C18: Dashine | D18: 124FtRQ2421400WL | E18: Advance paid to EPSE : | K18: 4000000
A19: 13 | B19: 45506 | C19: Awash | D19: 013041164408600 | E19: Advance paid to EPSE : | K19: 1400000
A20: 14 | B20: 45510 | C20: CBE | E20: Advance paid to EPSE : | K20: 2700000
A21: 15 | B21: 45511 | C21: CBE | E21: Advance paid to EPSE : | K21: 700000
A22: 16 | B22: 45513 | C22: CBE | D22: FT24222V3ZDQ | E22: Advance paid to EPSE : | K22: 3000000
A23: 17 | B23: 45513 | C23: CBE | D23: FT24222RF59F | E23: Advance paid to EPSE : | K23: 3500000
A24: 18 | B24: 45516 | C24: CBE | D24: FT242256N49B | E24: Advance paid to EPSE : | K24: 4000000
A25: 19 | B25: 45517 | C25: CBE | D25: FT24226D5254 | E25: Advance paid to EPSE : | K25: 2150000
A26: 20 | B26: 45517 | C26: Abysinya | D26: FT24226P0LHP | E26: Advance paid to EPSE : | K26: 850000
A27: 21 | B27: 45520 | C27: Dashen | D27: (mito) | E27: Advance paid to EPSE : | K27: 2000000
A28: 22 | B28: 45523 | C28: CBE | D28: FT24232YJ8MW | E28: Advance paid to EPSE : | K28: 4000000
A29: 23 | B29: 45523 | C29: Dashen | D29: 124FTRQ2423200WR | E29: Advance paid to EPSE : | K29: 2000000
A30: 24 | B30: 45525 | C30: CBE | D30: FT24234TINJS | E30: Advance paid to EPSE : | K30: 2500000
A31: 25 | B31: 45525 | C31: Abysinya | D31: FT24234LWN5K | E31: Advance paid to EPSE : | K31: 600000
A32: 26 | B32: 45525 | C32: CBE | D32: (Gesuba/W | E32: Advance paid to EPSE : | K32: 500000
A33: 27 | B33: 45533 | C33: CBE | D33: FT24242RVKXY | E33: Advance paid to EPSE : | K33: 4000000
... A53: 47 | B53: 45569 | C53: Abysinya | D53: FT24278DJXFM | E53: Advance paid to EPSE : | K53: 10000000
A54: 48 | B54: 45574 | C54: Brhan | E54: Advance paid to EPSE : | K54: 1700000
A55: 49 | B55: 45574 | C55: Dashen | D55: 124FTRQ24283000K | E55: Advance paid to EPSE : | K55: 3900000
A56: 50 | B56: 45575 | C56: CBE | D56: FT24284SSNNX | E56: Advance paid to EPSE : | K56: 1200000
A57: 51 | B57: 45575 | C57: Abysinya | D57: FT24284MGDXK | E57: Advance paid to EPSE : | K57: 2700000
A58: 52 | B58: 45578 | C58: CBE | D58: FT24290T94S6 | E58: Advance paid to EPSE : | K58: 4400000
A59: 53 | B59: 45582 | C59: CBE | D59: FT24291M57Q3 | E59: Advance paid to EPSE : | K59: 4300000
A60: 54 | B60: 45586 | C60: Dashen | D60: 124FTRQ2429500WW | E60: Advance paid to EPSE : | K60: 1400000
A61: 55 | B61: 45586 | C61: CBE | D61: FT24295XJZ8K | E61: Advance paid to EPSE : | K61: 8900000
...

Sheet Gesuba(Welaita)
A2: Advance collected from fuel station :
A4: SN | B4: Date | C4: Bank | D4: Reference | E4: Description | K4: Amounts
D5: Transfer From Last Year | K5: 8507482
A6: 1 | B6: 45488 | C6: CBE | D6: Ft24197LY4T9 | E6: Advance Collction | K6: 2770000
A7: 2 | B7: 45497 | C7: CBE | D7: FT24206D0W4K | E7: Advance Collction | K7: 2000000
A8: 3 | B8: 45497 | C8: Awash | D8: 013041164408600 | E8: Advance Collction | K8: 2000000
A9: 4 | B9: 45506 | C9: Awash | D9: 013041164408600 | E9: Advance Collction | K9: 1400000
A10: 5 | B10: 45513 | C10: CBE | D10: FT24222V6WPO | E10: Advance Collction | K10: 1000000
A11: 6 | B11: 45513 | C11: Awash | D11: 013041164408600 | E11: Advance Collction | K11: 1000000
A12: 7 | B12: 45517 | C12: CBE | D12: FT242267WCQ | E12: Advance Collction | K12: 2000000
A13: 8 | B13: 45517 | C13: Abysinya | D13: FT24226K01X5 | E13: Advance Collction | K13: 850000
A14: 9 | B14: 45525 | C14: CBE | D14: FT24234YZ25V | E14: Advance Collction | K14: 700000
A15: 10 | B15: 45525 | C15: Abysinya | D15: FT24234LWN5K | E15: Advance Collction | K15: 600000
A16: 11 | B16: 45539 | C16: CBE | D16: FT242480X6PG | E16: Advance Collction | K16: 1900000
A17: 12 | B17: 45539 | C17: Abysinya | D17: FT24248MXLCS | E17: Advance Collction | K17: 500000
... A30: 25 | B30: 45616 | C30: Abysinya | D30: FT2432546GTW | E30: Advance Collction Customer | K30: 1000000
A31: 26 | B31: 45631 | C31: Berhan | D31: 1.7333824e+16 | E31: Advance Collction Customer | K31: 1500000
A32: 27 | B32: 45631 | C32: Abysinya | D32: FT243409Y872 | E32: Advance Collction Customer | K32: 400000
A33: 28 | B33: 45631 | C33: Abysinya | D33: FT24340D30YH | E33: Advance Collction Customer | K33: 200000
A34: 29 | B34: 45631 | C34: CBE | D34: FT243403GZ8D | E34: Advance Collction Customer | K34: 2300000
A35: 30 | B35: 45643 | C35: Dashen | D35: 649FTRQ2435200WU | E35: Advance Collction Customer | K35: 4000000
A36: 31
A37: 32
A38: 33
A39: 34
A40: 35
A41: 36
A42: 37
A43: 38
A44: 39
A45: 40
A46: 41 | K46: =SUM(K5:K44) -> 58777482
E51: Fuel Sales for fuel station
B53: FDC# | C53: Loading Date | E53: Truck/Semi Trailor Plate No | F53: Origin | G53: Destination | H53: Type of Product | I53: QTY at 20 F | J53: Rate Per Litrs | K53: Total fuel Cost Amount (In Birr) (G= E*F)
D54: Driver's Name
A55: 1 | B55: 790007 | C55: 45482 | D55: Sintayehu Habtamu | E55: 3-91450/27736 | F55: Djb | G55: Gesuba(Welayta) | H55: MGR | I55: 47580 | J55: 79.2292 | K55: =I55*J55 -> 3769725.3
A56: 2 | B56: 796212 | C56: 45501 | D56: Tesfemariam Birhane | E56: 3-98387/29971 | F56: Djibouti | G56: Gesuba(Welayta) | H56: AGO | I56: 46811 | J56: 84.3292 | K56: =I56*J56 -> 3947534.2
A57: 3 | B57: 799506 | C57: 45510 | D57: Abebe Teka | E57: 3-94456/28742 | F57: Djibouti | G57: Gesuba(Welayta) | H57: MGR | I57: 45780 | J57: 83.1892 | K57: =I57*J57 -> 3808401.6
A58: 4 | B58: 803539 | C58: 45519 | D58: Ayalneh Asefa | E58: 3-81046/24745 | F58: Djibouti | G58: Gesuba(Welayta) | H58: AGO | I58: 50662 | J58: 84.3292 | K58: =I58*J58 -> 4272285.9
A59: 5 | B59: 809553 | C59: 45534 | D59: Gebrezgabher Teweldebrhan | E59: 3-93024/28706 | F59: Djibouti | G59: Gesuba(Welayta) | H59: MGR | I59: 45892 | J59: 83.1892 | K59: =I59*J59 -> 3817718.8
...

Sheet Metu(Elibabora)
A2: Advance collected from fuel station :
A4: SN | B4: Date | C4: Bank | D4: Reference | E4: Description | K4: Amounts
E5: Transfer From the Last year | K5: 4045926.2
A6: 1 | B6: 45483 | C6: CBE | D6: FT24192SC690 | K6: 4000000
A7: 2 | B7: 45490 | C7: CBE | D7: FT24199540P3 | K7: 4000000
A8: 2 | B8: 45499 | C8: CBE | D8: FT24208M5Z1K | K8: 4000000
A9: 3 | B9: 45516 | C9: CBE | D9: FT24225930Z1 | K9: 4000000
A10: 4 | B10: 45523 | C10: CBE | D10: FT24232D5H31 | K10: 4000000
A11: 5 | B11: 45533 | C11: CBE | D11: FT24242DS235 | K11: 4000000
A12: 6 | B12: 45554 | C12: CBE | D12: FT24263N0FV2 | K12: 4000000
A13: 7 | B13: 45561 | C13: CBE | D13: FT24270JPHS4 | K13: 2000000
A14: 8 | B14: 45567 | C14: CBE | D14: FT242763YLBF | K14: 2100000
A15: 9 | B15: 45582 | C15: CBE | D15: FT2429163WXL | K15: 4300000
A16: 10 | B16: 45586 | C16: CBE | D16: FT24295FLJXY | K16: 4300000
A17: 11 | B17: 45604 | C17: CBE | D17: FT24313QP6DB | K17: 4300000
... A19: 13 | B19: 45640 | C19: CBE | D19: FT24349TGMGB | K19: 4300000
A20: 14 | K20: 3000000
A21: 15
A22: 16
A23: 17
A24: 18
A25: 19
A26: 20
A27: 21
A28: 22
A29: 23
A30: 24
A31: 25
A32: 26
... A50: 44
E51: Total Advance collected | K51: =SUM(K5:K49) -> 60645926
E55: Fuel Sales for fuel station | M55: 11545926
A58: SN | B58: FDC# | C58: Loading Date | E58: Truck/Semi Trailor Plate No | F58: Origin | G58: Destination | H58: Type of Product | I58: QTY at 20 F | J58: Rate Per Litrs | K58: Total fuel Cost Amount (In Birr) (G= E*F)
D59: Driver's Name
A60: 1 | B60: 793663 | C60: 45493 | D60: Ayalneh Asefa | E60: 3-81046/24745 | F60: Djibouti | G60: Metu(Elibaboura | H60: AGO | I60: 50550 | J60: 85.8792 | K60: =I60*J60 -> 4341193.6
A61: 2 | B61: 796914 | C61: 45504 | D61: Kasahun Tona | E61: 3-93024/28706 | F61: Djibouti | G61: Metu(Elibaboura | H61: MGR | I61: 45726 | J61: 84.7392 | K61: =I61*J61 -> 3874784.7
A62: 3 | B62: 803064 | C62: 45519 | D62: Tesfemariam Birhane | E62: 3-98387/29971 | F62: Djibouti | G62: Metu(Elibaboura | H62: AGO | I62: 46860 | J62: 85.8792 | K62: =I62*J62 -> 4024299.3
A63: 4 | B63: 805662 | C63: 45525 | D63: Teshome Tesfaye | E63: 3-93434/28741 | F63: Djibouti | G63: Metu(Elibaboura | H63: AGO | I63: 45948 | J63: 85.8792 | K63: =I63*J63 -> 3945977.5
A64: 5 | B64: 811070 | C64: 45543 | D64: Andualem Demoz | E64: 3-90870/27584 | F64: Djibouti | G64: Metu(Elibaboura | H64: MGR | I64: 45431 | J64: 84.7392 | K64: =I64*J64 -> 3849786.6
A65: 6 | B65: 818476 | C65: 45562 | D65: Abebe Teka | E65: 3-94456/28742 | F65: Djibouti | G65: Metu(Elibaboura | H65: AGO | I65: 46063 | J65: 85.8792 | K65: =I65*J65 -> 3955853.6
...

Sheet Leha(Gofa)
A2: Advance collected from fuel station :
A4: SN | B4: Date | C4: Bank | D4: Reference | E4: Description | K4: Amounts
E5: Transfer From Last Year | K5: 9113228.5
A6: 1 | B6: 45499 | C6: Birhan | D6: 2500570132961 | E6: Advance Collection | K6: 4000000
A7: 2 | B7: 45513 | C7: Birhan | D7: 3012408095157684 | E7: Advance Collection Outgoing RTGS Advice to 1000547269989 | K7: 2500000
A8: 3 | B8: 45524 | C8: Birhan | D8: 3012408202582143 | E8: Advance Collection Outgoing RTGS Advice to 1000547269989 | K8: 3000000
A9: 4 | B9: 45537 | C9: Birhan | D9: 3012409026196526 | E9: Advance Collection Outgoing RTGS Advice to 1000628923527 | K9: 4000000
A10: 5 | B10: 45546 | C10: Birhan | D10: 2500570132961 | E10: Advance Collection | K10: 4000000
A11: 6 | B11: 45572 | C11: Birhan | D11: 2500570132961 | E11: Advance Collection | K11: 2000000
A12: 7 | B12: 45579 | C12: Birhan | D12: 2500570132961 | E12: Advance Collection | K12: 4300000
A13: 8 | B13: 45609 | C13: Birhan | D13: 1731483783117173489 | E13: Advance Collection | K13: 4300000
A14: 9 | B14: 45625 | C14: CBE | D14: FT24334CP26X | E14: Advance Collection | K14: 4300000
A15: 10 | B15: 45652 | C15: CBE | D15: FT24361P3X32 | E15: Advance Collection | K15: 4300000
A16: 11
A17: 12
A18: 13
A19: 14
A20: 15
A21: 16
A22: 17
A23: 18
A24: 19
A25: 20
A26: 20
A27: 21
... A47: 41
P48: 13113228
E51: Total Advance collected | K51: =SUM(K5:K49) -> 45813228 | M51: 13113228
E55: Fuel Sales for fuel station
A58: SN | B58: FDC# | C58: Loading Date | E58: Truck/Semi Trailor Plate No | F58: Origin | G58: Destination | H58: Type of Product | I58: QTY at 20 F | J58: Rate Per Litrs | K58: Total fuel Cost Amount (In Birr) (G= E*F)
D59: Driver's Name
A60: 1 | B60: 790978 | C60: 45493 | D60: Niguse Tadese | E60: 3-93449/28749 | F60: Djibouti | G60: Leha(gofa) | H60: MGR | I60: 45667 | J60: 84.8792 | K60: =I60*J60 -> 3876178.4
A61: 2 | B61: 802099 | C61: 45517 | D61: Weldekidan.Hailu | E61: 3-98388/29973 | F61: Djibouti | G61: Leha(gofa) | H61: AGO | I61: 46632 | J61: 86.0192 | K61: =I61*J61 -> 4011247.3
A62: 3 | B62: 805665 | C62: 45531 | D62: Getachew Alemshet | E62: 3-90951/27927 | F62: Djibouti | G62: Leha(gofa) | H62: MGR | I62: 45833 | J62: 84.8792 | K62: =I62*J62 -> 3890268.4
A63: 4 | B63: 813257 | C63: 45546 | D63: Weldekidan.Hailu | E63: 3-98388/29973 | F63: Djibouti | G63: Leha(gofa) | H63: AGO | I63: 46608 | J63: 86.0192 | K63: =I63*J63 -> 4009182.9
A64: 5 | B64: 821689 | C64: 45576 | D64: Tesfemariam Birhane | E64: 3-98387/29971 | F64: Djibouti | G64: Leha(gofa) | H64: MGR | I64: 46628 | J64: 93.4992 | K64: =I64*J64 -> 4359680.7
A65: 6 | B65: 823475 | C65: 45576 | D65: Nigus Tadese | E65: 3-93449/28749 | F65: Djibouti | G65: Leha(gofa) | H65: AGO | I65: 46048 | J65: 92.6392 | K65: =I65*J65 -> 4265849.9
A66: 7 | B66: 834606 | C66: 45605 | D66: Weldekidan.Hailu | E66: 3-98388/29973 | F66: Djibouti | G66: Leha(gofa) | H66: AGO | I66: 46552 | J66: 92.6392 | K66: =I66*J66 -> 4312540
A67: 8 | B67: 844579 | C67: 45633 | D67: Weldekidan.Hailu | E67: 3-98388/29973 | F67: Djibouti | G67: Leha(gofa) | H67: AGO | I67: 46755 | J67: 92.6392 | K67: =I67*J67 -> 4331345.8
A68: 9 | F68: Djibouti | K68: =I68*J68 -> 0
...

Sheet Mito(Silta)
A2: Advance collected from fuel station :
A4: SN | B4: Date | C4: Bank | D4: Reference | E4: Description | K4: Amounts
E5: Transfer From the last year | K5: 4035574.2
A6: 1 | B6: 45505 | C6: Dashen | D6: FT8FTRQ242140008 | K6: 4000000
A7: 2 | B7: 45519 | C7: Dashen | D7: F78FTRQ2422800WK | K7: 2000000
A8: 2 | B8: 45523 | C8: Dashen | D8: FT8FTRQ2423200WC | K8: 2000000
A9: 3 | B9: 45537 | C9: Dashen | D9: FT8FTRQ2424600Wq | K9: 3386280.4
A10: 4 | B10: 45559 | C10: Dashen | D10: F78FTRQ24800Wn | K10: 3800000
A11: 5 | B11: 45574 | C11: Dashen | D11: FT8FTRQ242830007 | K11: 3900000
A12: 6 | B12: 45576 | C12: Dashen | D12: FT8FTRQ2428500WH | K12: 200000
A13: 7 | B13: 45601 | C13: Dashen | D13: FT8FTRQ24310000U | K13: 4100000
A14: 8 | B14: 45601 | C14: Dashen | D14: FT8FTRQ24310000D | K14: 200000
A15: 9 | B15: 45612 | C15: Dashen | D15: F78FTRQ24321000E | K15: 4300000
A16: 10 | B16: 45636 | C16: Dashen | D16: FT8FTRQ2434500WW | K16: 1500000
A17: 11 | B17: 45642 | C17: Dashen | D17: FT8FTRQ243510015 | K17: 2500000
A18: 12
A19: 13
A20: 14
A21: 15
A22: 16
A23: 17
A24: 18
A25: 19
A26: 20
A27: 21
A28: 22
A29: 23
... A47: 41
E51: Total Advance collected | K51: =SUM(K5:K50) -> 35921855
E55: Fuel Sales for fuel station
A58: SN | B58: FDC# | C58: Loading Date | E58: Truck/Semi Trailor Plate No | F58: Origin | G58: Destination | H58: Type of Product | I58: QTY at 20 F | J58: Rate Per Litrs | K58: Total fuel Cost Amount (In Birr) (G= E*F)
D59: Driver's Name
A60: 1 | B60: 789278 | C60: 45481 | D60: Destalem Abreha | E60: 3-71435/21297 | F60: Djib0uti | G60: Mito(Silta) | H60: MGR | I60: 46483 | J60: 82.3292 | K60: =I60*J60 -> 3826908.2
A61: 2 | B61: 802080 | C61: 45516 | D61: Teweldebrhan G/zgabher | E61: 3-93601/28714 | F61: Djib0uti | G61: Mito(Silta) | H61: MGR | I61: 45688 | J61: 82.3292 | K61: =I61*J61 -> 3761456.5
A62: 3 | B62: 807109 | C62: 45528 | D62: Teweldebrhan G/zgabher | E62: 3-93601/28714 | F62: Djib0uti | G62: Mito(Silta) | H62: AGO | I62: 45927 | J62: 83.4692 | K62: =I62*J62 -> 3833489.9
A63: 4 | B63: 811543 | C63: 45548 | D63: Teweldebrhan G/zgabher | E63: 3-93601/28714 | F63: Djib0uti | G63: Mito(Silta) | H63: MGR | I63: 45598 | J63: 82.3292 | K63: =I63*J63 -> 3754046.9
A64: 5 | B64: 821685 | C64: 45571 | D64: Teshome Tesfaye | E64: 3-93434/28741 | F64: Djib0uti | G64: Mito(Silta) | H64: AGO | I64: 45905 | J64: 83.4692 | K64: =I64*J64 -> 3831653.6
A65: 6 | B65: 829745 | C65: 45591 | D65: Teweldebrhan G/zgabher | E65: 3-93601/28714 | F65: Djib0uti | G65: Mito(Silta) | H65: AGO | I65: 46082 | J65: 90.0192 | K65: =I65*J65 -> 4148264.8
A66: 7 | B66: 838248 | C66: 45616 | D66: Teshome Tesfaye | E66: 3-93434/28741 | F66: Djib0uti | G66: Mito(Silta) | H66: AGO | I66: 46204 | J66: 90.0192 | K66: =I66*J66 -> 4159247.1
A67: 8 | B67: 848143 | C67: 45656 | D67: Teshome Tesfaye | E67: 3-93434/28741 | F67: Djib0uti | G67: Mito(Silta) | H67: MGR | I67: 46077 | J67: 90.8792 | K67: =I67*J67 -> 4187440.9
...

Sheet Batu(Coustic Soda)
A2: Advance collected from fuel station :
A4: SN | B4: Date | C4: Bank | D4: Reference | E4: Description | K4: Amounts
E5: Transfer From Last year | K5: 2991274.8
A6: 1 | B6: 45498 | C6: CBE | D6: FT24207W59Q3 | E6: Advance Collection | K6: 6165120
A7: 2 | B7: 45509 | C7: CBE | D7: FT242185JRT9 | E7: Advance Collection | K7: 3082560
A8: 2
A9: 3
A10: 4
A11: 5
A12: 6
A13: 7
A14: 8
A15: 9
A16: 10
A17: 11
A18: 12
A19: 13
... A47: 41
E51: Total Advance collected | K51: =SUM(K5:K47) -> 12238955
E55: Fuel Sales for fuel station
A58: SN | B58: FDC# | C58: Loading Date | E58: Truck/Semi Trailor Plate No | F58: Origin | G58: Destination | H58: Type of Product | I58: QTY at 20 F | J58: Rate Per Litrs | K58: Total fuel Cost Amount (In Birr) (G= E*F)
D59: Driver's Name
A60: 1 | B60: 786564 | C60: 45487 | D60: Wedneh Bekele | E60: 3-93601/28714 | F60: Djibouti | G60: Batu(Coustic | H60: HFO | I60: 45946 | J60: 64.31 | K60: =I60*J60 -> 2954787.3
A61: 2 | B61: 796916 | C61: 45501 | D61: Getachew Alemshet | E61: 3-90951/27927 | F61: Djibouti | G61: Batu(Coustic | H61: HFO | I61: 45961 | J61: 64.31 | K61: =I61*J61 -> 2955751.9
A62: 3 | B62: 801261 | C62: 45512 | D62: Nigus Tadese | E62: 3-93449/28749 | F62: Djibouti | G62: Batu(Coustic | H62: HFO | I62: 45771 | J62: 64.31 | K62: =I62*J62 -> 2943533
A63: 4 | B63: 816619 | C63: 45555 | D63: Teshome Tesfaye | E63: 3-93434/29741 | F63: Djibouti | G63: Batu(Coustic | H63: HFO | I63: 46036 | J63: 64.31 | K63: =I63*J63 -> 2960575.2
A64: 5 | F64: Djibouti | K64: =I64*J64 -> 0
A65: 6 | F65: Djibouti | K65: =I65*J65 -> 0
A66: 7 | F66: Djibouti | K66: =I66*J66 -> 0
A67: 8 | F67: Djibouti | K67: =I67*J67 -> 0
A68: 9 | F68: Djibouti | K68: =I68*J68 -> 0
A69: 10 | F69: Djibouti | K69: =I69*J69 -> 0
A70: 11 | F70: Djibouti | K70: =I70*J70 -> 0
A71: 12 | F71: Djibouti | K71: =I71*J71 -> 0
A72: 13 | F72: Djibouti | K72: =I72*J72 -> 0
A73: 14 | F73: Djibouti | K73: =I73*J73 -> 0
A74: 15 | F74: Djibouti | K74: =I74*J74 -> 0
A75: 16 | F75: Djibouti | K75: =I75*J75 -> 0
... A85: 26 | F85: Djibouti | K85: =I85*J85 -> 0
A86: total | K86: =SUM(K60:K85) -> 11814647
...

Sheet Dashine(Gonder)
F1: Dashine(Berwery) | H1: Factory
A2: Advance collected from fuel station :
A4: SN | B4: Date | C4: Bank | D4: Reference | E4: Description | K4: Amounts | L4: Loss | M4: Price | N4: Total Loss in birr | O4: Plate No
E5: Transfer From Last year | K5: 6795274.1 | L5: 3866 | M5: 64.95 | N5: =L5*M5 -> 251096.7 | O5: 3-93643
A6: 1 | B6: 45600 | C6: Abyssinya | D6: FT24278764RP | E6: Advance Collection Diller | K6: 10000000 | L6: 4087 | M6: 64.95 | N6: =L6*M6 -> 265450.65 | O6: 3-93045
A7: 2 | B7: 45600 | C7: Abyssinya | D7: FT2430928P4 | E7: Advance Collection Diller | K7: 5000000 | L7: 2920 | M7: 64.95 | N7: =L7*M7 -> 189654 | O7: 3-93449
A8: 2 | C8: Abyssinya | D8: FT2430928P4 | E8: Advance Collection Diller | K8: 5000000 | L8: 736 | M8: 64.95 | N8: =L8*M8 -> 47803.2 | O8: 3-90951
A9: 3 | B9: 45639 | C9: Abyssinya | D9: FT24348ZX59M | E9: Advance Collection Diller | K9: 8000000 | L9: 735 | M9: 64.95 | N9: =L9*M9 -> 47738.25 | O9: 3-93434
A10: 4 | N10: =SUM(N5:N9) -> 801742.8
A11: 5
A12: 6 | N12: =N10+K94 -> 8721007.4
A13: 7
A14: 8
A15: 9
A16: 10
A17: 11
A18: 12
A19: 13 | N19: =K5+N10 -> 7597016.9
A20: 14
A21: 15
A22: 16
A23: 17
A24: 18
A25: 19
A26: 20
A27: 21
A28: 22
A29: 23
A30: 24
A31: 25
... A47: 41
E51: Total Advance collected | K51: =SUM(K5:K50) -> 34795274
E55: Fuel Sales for fuel station
A58: SN | B58: FDC# | C58: Loading Date | E58: Truck/Semi Trailor Plate No | F58: Origin | G58: Destination | H58: Type of Product | I58: QTY at 20 F | J58: Rate Per Litrs | K58: Total fuel Cost Amount (In Birr) (G= E*F) | M58: New Price
D59: Driver's Name
A60: 1 | B60: 809183 | C60: 45535 | D60: Niguse Tadese | E60: 3-93449/28749 | F60: Djibouti | G60: Dashen(Gonder) | H60: LFO | I60: 46344 | J60: 64.95 | K60: =I60*J60 -> 3010042.8 | M60: 72.1
A61: 2 | B61: 821691 | C61: 45572 | D61: Endalk Kibret | E61: 3-93865/29153 | F61: Djibouti | G61: Dashen(Gonder) | H61: LFO | I61: 48448 | J61: 68.07 | K61: =I61*J61 -> 3297855.4 | M61: 106.84 | N61: Through A.A
A62: 3 | B62: 829003 | C62: 45590 | D62: Musa Adem | E62: 3-94462/28942 | F62: Djibouti | G62: Dashen(Gonder) | H62: LFO | I62: 46470 | J62: 102.97 | K62: =I62*J62 -> 4785015.9 | M62: 102.97 | N62: Through Weldya
A63: 4 | B63: 833747 | C63: 45604 | D63: Musa Adem | E63: 3-94462/28942 | F63: Djibouti | G63: Dashen(Gonder) | H63: LFO | I63: 46431 | J63: 102.97 | K63: =I63*J63 -> 4781000.1
A64: 5 | B64: 839955 | C64: 45620 | D64: Endalk Kibret | E64: 3-93865/29153 | F64: Djibouti | G64: Dashen(Gonder) | H64: LFO | I64: 48516 | J64: 111.84 | K64: =I64*J64 -> 5426029.4
...

Sheet Dubti(Sordo)
A2: Advance collected from fuel station :
A4: SN | B4: Date | C4: Bank | D4: Reference | E4: Description | K4: Amounts
A5: 1 | B5: 45507 | C5: CBE | D5: FT24216W1N!D | E5: Advance Collection | K5: 850000
A6: 2 | B6: 45511 | C6: CBE | D6: FT24220PrBKG | E6: Advance Collection | K6: 550000
A7: 2
A8: 3
A9: 4
A10: 5
A11: 6
A12: 7
A13: 8
A14: 9
A15: 10
A16: 11
A17: 12
A18: 13
... A46: 41
E47: Total Advance collected | K47: =SUM(K5:K46) -> 1400000
E54: Fuel Sales for fuel station
A57: SN | B57: FDC# | C57: Loading Date | E57: Truck/Semi Trailor Plate No | F57: Origin | G57: Destination | H57: Type of Product | I57: QTY at 20 F | J57: Rate Per Litrs | K57: Total fuel Cost Amount (In Birr) (G= E*F)
D58: Driver's Name
A59: 1 | B59: 797320 | C59: 45501 | D59: Destalem Abreha | E59: 3-71435/21297 | F59: Djibouti | G59: DubtiAfar | H59: AGO | I59: 46860 | J59: 79.4492 | K59: =I59*J59 -> 3722989.5
A60: 2 | F60: Djibouti
A61: 3 | F61: Djibouti
A62: 4 | F62: Djibouti
A63: 5 | F63: Djibouti
A64: 6 | F64: Djibouti
A65: 7 | F65: Djibouti
A66: 8 | F66: Djibouti
A67: 9 | F67: Djibouti
A68: 10 | F68: Djibouti
A69: 11 | F69: Djibouti
A70: 12 | F70: Djibouti
A71: 13 | F71: Djibouti
... A84: 26 | F84: Djibouti
A85: total | K85: =SUM(K59:K84) -> 3722989.5
E91: Grand Total fuels sales | K91: =K85 -> 3722989.5
E93: Account Receivable(Payable ) | K93: =K47-K91 -> -2322989.5

Sheet Mykadra
A2: Advance collected from fuel station :
A4: SN | B4: Date | C4: Bank | D4: Reference | E4: Description | K4: Amounts
A5: 1 | B5: 45495 | C5: CBE | D5: FT24204JHQ3N | E5: Advance Collection | K5: 1894000
A6: 2 | B6: 45495 | C6: Abysinya | D6: FT24204YJ4FC | E6: Advance Collection | K6: 854000
A7: 2 | B7: 45495 | C7: Abysinya | D7: FT242048N5T1 | E7: Advance Collection | K7: 374000
A8: 3 | B8: 45495 | C8: CBE | D8: FT242045RG4G | E8: Advance Collection | K8: 152000
A9: 4 | B9: 45496 | C9: CBE | E9: Advance Collection | K9: 321000
A10: 5
A11: 6
A12: 7
A13: 8
A14: 9
A15: 10
A16: 11
A17: 12
A18: 13
A19: 14
A20: 15
A21: 16
... A46: 41
E47: Total Advance collected | K47: =SUM(K5:K46) -> 3595000
E54: Fuel Sales for fuel station
A57: SN | B57: FDC# | C57: Loading Date | E57: Truck/Semi Trailor Plate No | F57: Origin | G57: Destination | H57: Type of Product | I57: QTY at 20 F | J57: Rate Per Litrs | K57: Total fuel Cost Amount (In Birr) (G= E*F)
D58: Driver's Name
A59: 1 | B59: 790976 | C59: 45485 | D59: Musa Adem | E59: 3-94462/28942 | F59: Djibouti | G59: Mykadra | H59: AGO | I59: 45977 | J59: 84.7892 | K59: =I59*J59 -> 3898353
A60: 2 | F60: Djibouti
A61: 3 | F61: Djibouti
A62: 4 | F62: Djibouti
A63: 5 | F63: Djibouti
A64: 6 | F64: Djibouti
A65: 7 | F65: Djibouti
A66: 8 | F66: Djibouti
A67: 9 | F67: Djibouti
A68: 10 | F68: Djibouti
A69: 11 | F69: Djibouti
A70: 12 | F70: Djibouti
A71: 13 | F71: Djibouti
... A84: 26 | F84: Djibouti
A85: total | K85: =SUM(K59:K84) -> 3898353
E91: Grand Total fuels sales | K91: =K85 -> 3898353
...

Sheet S.Humera
A2: Advance collected from fuel station :
A4: SN | B4: Date | C4: Bank | D4: Reference | E4: Description | K4: Amounts
A5: 1 | B5: 45630 | C5: Abysinya | D5: FT2433KIL5GUAY | E5: Advance Collected From Diler | K5: 1900000
A6: 2 | B6: 45630 | C6: Awash | D6: 013041164408600 | E6: Advance Collected From Diler | K6: 2100000
A7: 2 | B7: 45637 | C7: CBE | D7: FT24346L2FMW | E7: Advance Collected From Diler | K7: 3000000
A8: 3 | E8: Advance Collected From Diler
A9: 4 | E9: Advance Collected From Diler
A10: 5 | E10: Advance Collected From Diler
A11: 6 | E11: Advance Collected From Diler
A12: 7 | E12: Advance Collected From Diler
A13: 8 | E13: Advance Collected From Diler
A14: 9 | E14: Advance Collected From Diler
A15: 10 | E15: Advance Collected From Diler
A16: 11 | E16: Advance Collected From Diler
A17: 12 | E17: Advance Collected From Diler
A18: 13 | E18: Advance Collected From Diler
A19: 14 | E19: Advance Collected From Diler
... A22: 17 | E22: Advance Collected From Diler
A23: 18
A24: 19
A25: 20
A26: 21
A27: 22
A28: 23
A29: 24
A30: 25
A31: 26
A32: 27
A33: 28
A34: 29
... A46: 41
E47: Total Advance collected | K47: =SUM(K5:K46) -> 7000000
E54: Fuel Sales for fuel station
A57: SN | B57: FDC# | C57: Loading Date | E57: Truck/Semi Trailor Plate No | F57: Origin | G57: Destination | H57: Type of Product | I57: QTY at 20 F | J57: Rate Per Litrs | K57: Total fuel Cost Amount (In Birr) (G= E*F)
D58: Driver's Name
A59: 1 | B59: 839959 | C59: 45620 | D59: Getachew Alemshet | E59: 3-94462/27927 | F59: Djibouti | G59: S.Humera | H59: AGO | I59: 46264 | J59: 91.1992 | K59: =I59*J59 -> 4219239.8
A60: 2 | B60: 844221 | C60: 45636 | D60: Nigus Birhane | E60: 3-89959/27428 | F60: Djibouti | G60: S.Humera | H60: MGR | I60: 47305 | J60: 92.0592 | K60: =I60*J60 -> 4354860.5
A61: 3 | F61: Djibouti | K61: =I61*J61 -> 0
A62: 4 | F62: Djibouti | K62: =I62*J62 -> 0
A63: 5 | F63: Djibouti | K63: =I63*J63 -> 0
...

Sheet Adebay
A2: Advance collected from fuel station :
A4: SN | B4: Date | C4: Bank | D4: Reference | E4: Description | K4: Amounts
A5: 1 | B5: 45604 | C5: CBE | D5: FT243130XSSM | E5: Advance Collection | K5: 3300000
A6: 2 | B6: 45604 | C6: Awash | D6: 013041164408600 | E6: Advance Collection | K6: 1000000
A7: 2 | B7: 45614 | C7: CBE | D7: FT24323TH1GF | E7: Advance Collection From Dilers | K7: 2000000
A8: 3 | B8: 45614 | C8: Awash | D8: 013041164408600 | E8: Advance Collection From Dilers | K8: 2100000
A9: 4
A10: 5
A11: 6
A12: 7
A13: 8
A14: 9
A15: 10
A16: 11
A17: 12
A18: 13
A19: 14
A20: 15
... A46: 41
D50: Total Advance collected | K50: =SUM(K5:K45) -> 8400000
E54: Fuel Sales for fuel station
A56: SN | B56: FDC# | C56: Loading Date | E56: Truck/Semi Trailor Plate No | F56: Origin | G56: Destination | H56: Type of Product | I56: QTY at 20 F | J56: Rate Per Litrs | K56: Total fuel Cost Amount (In Birr) (G= E*F)
D57: Driver's Name
A58: 1 | B58: 834611 | C58: 45607 | D58: Sintayehu Esheta | E58: 3-91450/27736 | F58: Djibouti | G58: Adebay | H58: AGO | I58: 48475 | J58: 91.2992 | K58: =I58*J58 -> 4425728.7
A59: 2 | B59: 838249 | C59: 45618 | D59: Nigus Birhane | E59: 3-89959/27428 | F59: Djibouti | G59: Adebay | H59: MGR | I59: 47340 | J59: 92.1592 | K59: =I59*J59 -> 4362816.5
A60: 3 | F60: Djibouti | K60: =I60*J60 -> 0
A61: 4 | F61: Djibouti | K61: =I61*J61 -> 0
A62: 5 | F62: Djibouti | K62: =I62*J62 -> 0
A63: 6 | F63: Djibouti | K63: =I63*J63 -> 0
A64: 7 | F64: Djibouti | K64: =I64*J64 -> 0
A65: 8 | F65: Djibouti | K65: =I65*J65 -> 0
A66: 9 | F66: Djibouti | K66: =I66*J66 -> 0
A67: 10 | F67: Djibouti | K67: =I67*J67 -> 0
A68: 11 | F68: Djibouti | K68: =I68*J68 -> 0
A69: 12 | F69: Djibouti | K69: =I69*J69 -> 0
A70: 13 | F70: Djibouti | K70: =I70*J70 -> 0
A71: 14 | F71: Djibouti | K71: =I71*J71 -> 0
... A83: 26 | F83: Djibouti | K83: =I83*J83 -> 0
B84: total | K84: =SUM(K58:K83) -> 8788545.2
E90: Grand Total fuels sales | K90: =K84 -> 8788545.2
...

Sheet Baeker
A2: Advance collected from fuel station :
A4: SN | B4: Date | C4: Bank | D4: Reference | E4: Description | K4: Amounts
A5: 1 | B5: 45533 | C5: CBE | D5: FT2424265FC3 | E5: Collected From Others(Baro Tesfaye Yideg) | K5: 2000000
A6: 2 | B6: 45538 | C6: CBE | D6: FT24247FFZ3L | E6: Collected From Others(Baro Tesfaye Yideg) | K6: 1200000
A7: 2 | B7: 45548 | C7: CBE | D7: FT24257GZGWH | E7: Advance Collection | K7: 4000000
A8: 3 | B8: 45567 | C8: CBE | E8: Advance Collection | K8: 4000000
A9: 4 | B9: 45625 | C9: CBE | D9: FT24334GX1WW | E9: Advance Collection | K9: 3500000
A10: 5 | B10: 45625 | C10: Awash | D10: 013041164408600 | E10: Advance Collection | K10: 600000
A11: 6 | B11: 45651 | C11: Abysinya | D11: FT24360/24824 | E11: Advance Collection | K11: 12000000
A12: 7
A13: 8
A14: 9
A15: 10
A16: 11
A17: 12
A18: 13
A19: 14
A20: 15
A21: 16
A22: 17
A23: 18
... A46: 41
E50: Total Advance collected | K50: =SUM(K6:K46) -> 25300000
E54: Fuel Sales for fuel station
A57: SN | B57: FDC# | C57: Loading Date | E57: Truck/Semi Trailor Plate No | F57: Origin | G57: Destination | H57: Type of Product | I57: QTY at 20 F | J57: Rate Per Litrs | K57: Total fuel Cost Amount (In Birr) (G= E*F)
D58: Driver's Name
A59: 1 | B59: 797987 | C59: 45503 | D59: Musa Adem | E59: 3-94462/28942 | F59: Djibouti | G59: Baeker | H59: AGO | I59: 45963 | J59: 84.3492 | K59: =I59*J59 -> 3876942.3
A60: 2 | B60: 814019 | C60: 45549 | D60: Musa Adem | E60: 3-94462/28942 | F60: Djibouti | G60: Baeker | H60: AGO | I60: 46001 | J60: 84.3492 | K60: =I60*J60 -> 3880147.5
A61: 3 | B61: 820817 | C61: 45570 | D61: Musa Adem | E61: 3-94462/28942 | F61: Djibouti | G61: Baeker | H61: AGO | I61: 46065 | J61: 84.3492 | K61: =I61*J61 -> 3885545.9
A62: 4 | B62: 836718 | C62: 45610 | D62: Getachew Alemshet | E62: 3-90951/27927 | F62: Djibouti | G62: Baeker | H62: AGO | I62: 46272 | J62: 90.9292 | K62: =I62*J62 -> 4207475.9
A63: 5 | B63: 842513 | C63: 45626 | D63: Getachew Alemshet | E63: 3-90951/27927 | F63: Djibouti | G63: Baeker | H63: AGO | I63: 46251 | J63: 90.9292 | K63: =I63*J63 -> 4205566.4
A64: 6 | F64: Djibouti | K64: =I64*J64 -> 0
A65: 7 | F65: Djibouti | K65: =I65*J65 -> 0
A66: 8 | F66: Djibouti | K66: =I66*J66 -> 0
A67: 9 | F67: Djibouti | K67: =I67*J67 -> 0
A68: 10 | F68: Djibouti | K68: =I68*J68 -> 0
A69: 11 | F69: Djibouti | K69: =I69*J69 -> 0
A70: 12 | F70: Djibouti | K70: =I70*J70 -> 0
A71: 13 | F71: Djibouti | K71: =I71*J71 -> 0
A72: 14 | F72: Djibouti | K72: =I72*J72 -> 0
...

Sheet Dansha(Wendem)
A2: Advance collected from fuel station :
A4: SN | B4: Date | C4: Bank | D4: Reference | E4: Description | L4: Amounts | N4: 110588.71 | O4: Transfer From Last year
A5: 1 | B5: 45556 | C5: CBE | D5: FT24265D9LX | E5: Advance Collection | L5: 4200000
A6: 2 | B6: 45579 | C6: CBE | D6: FT24288MTYY6 | E6: Advance Collection | L6: 467930
A7: 2 | B7: 45596 | C7: CBE | D7: FT243051DWQO | E7: Advance Collection | L7: 4200000
A8: 3 | B8: 45607 | C8: CBE | D8: FT243657VRLB | E8: Advance Collection | L8: 302410 | M8: NB | N8: 89100 | O8: Fuel From Station | P8: to Sintayehu
A9: 4 | B9: 45621 | C9: CBE | D9: FT24330LGTWG | E9: Advance Collection | L9: 3500000 | N9: 50000 | O9: Abel | P9: to Sintayehu
A10: 5 | B10: 45639 | C10: CBE | D10: FT243486R7DN | E10: Advance Collection | L10: 1000000
A11: 6 | B11: 45646 | C11: CBE | D11: FT24355FJSXB | E11: Advance Collection | L11: 151392
A12: 7 | B12: 45656 | C12: CBE | D12: FT243657VRLB | E12: Advance Collection | L12: 4000000
A13: 8
A14: 9
A15: 10
A16: 11
A17: 12
A18: 13
A19: 14
A20: 15
A21: 16
A22: 17
A23: 18
A24: 19
... A46: 41
E47: Total Advance collected | L47: =SUM(L5:L46) -> 17821732
E54: Fuel Sales for fuel station
A57: SN | B57: FDC# | C57: Loading Date | E57: Truck/Semi Trailor Plate No | F57: Origin | G57: Destination | H57: Type of Product | I57: QTY at 20 F | J57: Rate Per Litrs | K57: Rate Per Litrs | L57: Total fuel Cost Amount (In Birr) (G= E*F)
D58: Driver's Name
F59: Credit Transfer from Last year | G59: ast year | L59: 110588.71 | N59: 110588.71 | O59: Transfer from Last | P59: ast year
A60: 1 | B60: 820815 | C60: 45570 | D60: Sintayehu Esheta | E60: 3-91450/27736 | F60: Djibouti | G60: Dansha | H60: AGO | I60: 48110 | J60: 84.0592 | L60: =I60*J60 -> 4044088.1 | N60: 131810 | O60: 900 Fuel +50,000.00 | P60: Abel | Q60: 336,120 to Kumbi
A61: 2 | B61: 832406 | C61: 45600 | D61: Endalk Kbret | E61: 3-93865/29153 | F61: Djibouti | G61: Dansha | H61: AGO | I61: 48210 | J61: 90.6292 | L61: =I61*J61 -> 4369233.7 | N61: 302410 | O61: to Kumbi
A62: 3 | B62: 846854 | C62: 45639 | D62: Sintayehu Esheta | E62: 3-91450/27736 | F62: Djibouti | G62: Dansha | H62: AGO | I62: 48452 | J62: 90.6292 | L62: =I62*J62 -> 4391166 | N62: 139100 | O62: 900 Fuel +50,000.00
A63: 4 | B63: 854861 | C63: 45659 | D63: Endalk Kbret | E63: 3-93865/29153 | F63: Djibouti | G63: Dansha | H63: AGO | I63: 48324 | J63: 90.6292 | L63: =I63*J63 -> 4379565.5
A64: 5 | F64: Djibouti | L64: =I64*J64 -> 0
A65: 6 | F65: Djibouti | L65: =I65*J65 -> 0
A66: 7 | F66: Djibouti | L66: =I66*J66 -> 0
A67: 8 | F67: Djibouti | L67: =I67*J67 -> 0
A68: 9 | F68: Djibouti | L68: =I68*J68 -> 0
A69: 10 | F69: Djibouti | L69: =I69*J69 -> 0
A70: 11 | F70: Djibouti | L70: =I70*J70 -> 0
A71: 12 | F71: Djibouti | L71: =I71*J71 -> 0
...

Sheet Gonder Bikl Factory
B1: Gonder(Malte) Factory
A2: Advance collected from fuel station :
A4: SN | B4: Date | C4: Bank | D4: Reference | E4: Description | K4: Amounts
A5: 1 | B5: 45496 | C5: Abay | D5: 202FTRQ242050069 | E5: Advance Collection | K5: 4281600
A6: 2
A7: 2
A8: 3
A9: 4
A10: 5
A11: 6
A12: 7
A13: 8
A14: 9
A15: 10
A16: 11
A17: 12
... A45: 40
A46: 41 | E46: )
E50: Total Advance collected | K50: =SUM(K5:K46) -> 4281600
E54: Fuel Sales for fuel station
A57: SN | B57: FDC# | C57: Loading Date | E57: Truck/Semi Trailor Plate No | F57: Origin | G57: Destination | H57: Type of Product | I57: QTY at 20 F | J57: Rate Per Litrs | K57: Total fuel Cost Amount (In Birr) (G= E*F) | L57: New Price
D58: Driver's Name
A59: 1 | B59: 797574 | C59: 45507 | D59: Sintayehu Esheta | E59: 3-91450/27736 | F59: Djibouti | G59: Donder(Bikil | H59: HFO | I59: 48094 | J59: 71.36 | K59: =I59*J59 -> 3431987.8
A60: 2 | F60: Djibouti | K60: =I60*J60 -> 0 | L60: 104.83
A61: 3 | F61: Djibouti | K61: =I61*J61 -> 0
A62: 4 | F62: Djibouti | K62: =I62*J62 -> 0
A63: 5 | F63: Djibouti | K63: =I63*J63 -> 0
A64: 6 | F64: Djibouti | K64: =I64*J64 -> 0
A65: 7 | F65: Djibouti | K65: =I65*J65 -> 0
A66: 8 | F66: Djibouti | K66: =I66*J66 -> 0
A67: 9 | F67: Djibouti | K67: =I67*J67 -> 0
A68: 10 | F68: Djibouti | K68: =I68*J68 -> 0
A69: 11 | F69: Djibouti | K69: =I69*J69 -> 0
A70: 12 | F70: Djibouti | K70: =I70*J70 -> 0
A71: 13 | F71: Djibouti | K71: =I71*J71 -> 0
A72: 14 | F72: Djibouti | K72: =I72*J72 -> 0
... A84: 26 | F84: Djibouti | K84: =I84*J84 -> 0
A85: total | K85: =SUM(K59:K84) -> 3431987.8
E91: Grand Total fuels sales | K91: =K85 -> 3431987.8
E93: Account Receivable(Payable ) | K93: =K50-K91 -> 849612.16

Sheet Deposit From  Others
C1: Deposit From Other Componys | F1: panys
A2: Advance collected from fuel station :
A4: SN | B4: Date | C4: Bank | D4: Reference | E4: Description | K4: Amounts
A5: 1 | B5: 45533 | C5: CBE | D5: FT2424265FC3 | E5: Collected From Others(Baro Tesfaye Yideg) | K5: 2000000
A6: 2 | B6: 45538 | C6: CBE | D6: FT24247FFZ3L | E6: Collected From Others(Baro Tesfaye Yideg) | K6: 1200000
A7: 2 | B7: 45608 | C7: Awash | D7: 106412112416321988020 | E7: Collected From Others(Baro Tesfaye Yideg) | G7: Temesgen | H7: Yideg | K7: 1800000
A8: 3
A9: 4
A10: 5
A11: 6
A12: 7
A13: 8
A14: 9
A15: 10
A16: 11
A17: 12
A18: 13
A19: 14
... A45: 40
A46: 41 | E46: )
E50: Total Advance collected | K50: =SUM(K5:K46) -> 5000000
E54: Fuel Sales for fuel station
A57: SN | B57: FDC# | C57: Loading Date | E57: Truck/Semi Trailor Plate No | F57: Origin | G57: Destination | H57: Type of Product | I57: QTY at 20 F | J57: Rate Per Litrs | K57: Total fuel Cost Amount (In Birr) (G= E*F)
D58: Driver's Name | M58: 3434306.5
A59: 1 | M59: 3200000
A60: 2 | M60: =M58-M59 -> 234306.55
A61: 3 | F61: Djibouti | K61: =I61*J61 -> 0
A62: 4 | F62: Djibouti | K62: =I62*J62 -> 0
A63: 5 | F63: Djibouti | K63: =I63*J63 -> 0
A64: 6 | F64: Djibouti | K64: =I64*J64 -> 0
A65: 7 | F65: Djibouti | K65: =I65*J65 -> 0
A66: 8 | F66: Djibouti | K66: =I66*J66 -> 0
A67: 9 | F67: Djibouti | K67: =I67*J67 -> 0
A68: 10 | F68: Djibouti | K68: =I68*J68 -> 0
A69: 11 | F69: Djibouti | K69: =I69*J69 -> 0
A70: 12 | F70: Djibouti | K70: =I70*J70 -> 0
A71: 13 | F71: Djibouti | K71: =I71*J71 -> 0
A72: 14 | F72: Djibouti | K72: =I72*J72 -> 0
... A84: 26 | F84: Djibouti | K84: =I84*J84 -> 0
A85: total | K85: =SUM(K59:K84) -> 0
...

Sheet Dansha(Tegegne)
A2: Advance collected from fuel station :
A4: SN | B4: Date | C4: Bank | D4: Reference | E4: Description | L4: Amounts
A5: 1
A6: 2
A7: 2
A8: 3
A9: 4
A10: 5
A11: 6
A12: 7
A13: 8
A14: 9
A15: 10
A16: 11
... A46: 41
E47: Total Advance collected | L47: =SUM(L5:L46) -> 0
E54: Fuel Sales for fuel station
A57: SN | B57: FDC# | C57: Loading Date | E57: Truck/Semi Trailor Plate No | F57: Origin | G57: Destination | H57: Type of Product | I57: QTY at 20 F | J57: Rate Per Litrs | K57: Rate Per Litrs | L57: Total fuel Cost Amount (In Birr) (G= E*F)
D58: Driver's Name
F59: Djibouti
A60: 1 | F60: Djibouti
A61: 2 | F61: Djibouti
A62: 3 | F62: Djibouti
A63: 4 | F63: Djibouti
A64: 5 | F64: Djibouti
A65: 6 | F65: Djibouti
A66: 7 | F66: Djibouti
A67: 8 | F67: Djibouti
A68: 9 | F68: Djibouti
A69: 10 | F69: Djibouti
A70: 11 | F70: Djibouti
A71: 12 | F71: Djibouti
... A85: 26 | F85: Djibouti
A86: total | L86: =SUM(L59:L85) -> 0
E92: Grand Total fuels sales | L92: =L86 -> 0
E94: Account Receivable(Payable ) | L94: =L47-L92 -> 0

Sheet Sheet1
G4: Fuel Costs -EPSE
C5: 2
C6: 3 | D6: FDC# | E6: Loading Date | G6: Truck/Semi Trailor Plate No | H6: Origin | I6: Destination | J6: Type of Product | K6: QTY at 20 F | L6: Fuel cost Per Litrs | M6: Total fuel Cost Amount (In Birr) (G= E*F) | R6: 3 | S6: FDC# | T6: Loading Date | V6: Truck/Semi Trailor Plate No | W6: Origin | X6: Destination | Y6: Type of Product | Z6: QTY at 20 F | AA6: Fuel cost Per Litrs | AB6: Total fuel Cost Amount (In Birr) (G= E*F)
C7: 4 | F7: Driver's Name | R7: 4 | U7: Driver's Name
C8: 5 | D8: 789278 | E8: 45481 | F8: Destalem Abreha | G8: 3-71435/21297 | H8: Djb | I8: Mito(Silta) | J8: MGR | K8: 46483 | L8: 71.6167 | M8: =K8*L8 -> 3328959.1 | R8: 1 | S8: 839955 | T8: 45620 | U8: Tsegay | V8: 3-93865/29153 | W8: Djb | X8: Dashen | Y8: LFO | Z8: 48516 | AA8: 93.5632 | AB8: =Z8*AA8 -> 4539312.2
C9: 6 | D9: 790007 | E9: 45482 | F9: Sintayehu Esheta | G9: 3-91450/27736 | H9: Djb | I9: Gesuba(Welaita | J9: MGR | K9: 47580 | L9: 71.6167 | M9: =K9*L9 -> 3407522.6
C10: 7 | D10: 790976 | E10: 45485 | F10: Musa Adem | G10: 3-94462/28942 | H10: Djb | I10: Mykadra | J10: AGO | K10: 45977 | L10: 76.5447 | M10: =K10*L10 -> 3519295.7
C11: 8 | D11: 791486 | E11: 45486 | F11: Hassen Mehamed | G11: 3-94456/28742 | H11: Djb | I11: Awash | J11: AGO | K11: 46047 | M11: =K11*L11 -> 0
C12: 9 | D12: 791850 | E12: 45486 | F12: Tsehaye G/medhn | G12: 3-93045/28723 | H12: Djb | I12: Awash | J12: AGO | K12: 45918 | M12: =K12*L12 -> 0
C13: 10 | D13: 791485 | E13: 45487 | F13: Tesfemariam Birhane | G13: 3-98387/29971 | H13: Djb | I13: Awash | J13: AGO | K13: 46792 | M13: =K13*L13 -> 0
C14: 11 | D14: 786564 | E14: 45487 | F14: Wedneh Bekele | G14: 3-93601/28714 | H14: Djb | I14: Batu(Coustc | J14: HFO | K14: 45946 | L14: 57.7473 | M14: =K14*L14 -> 2653257.4
C15: 12 | D15: 790976 | E15: 45493 | F15: Niguse Tadese | G15: 3-93449/28749 | H15: Djb | I15: Leha(Gofa) | J15: MGR | K15: 45667 | L15: 75.4077 | M15: =K15*L15 -> 3443643.4
C16: 13 | D16: 793663 | E16: 45493 | F16: Ayalneh Asefa | G16: 3-81046/24745 | H16: Djb | I16: Metu(Elibaboura | J16: AGO | K16: 50550 | L16: 76.5447 | M16: =K16*L16 -> 3869334.6
C17: 14 | D17: 796212 | E17: 45498 | F17: Tesfemariam Birhane | G17: 3-98387/29971 | H17: Djb | I17: Gesuba(Welaita | J17: AGO | K17: 46811 | L17: 76.5447 | M17: =K17*L17 -> 3583134
C18: 15 | D18: 796916 | E18: 45501 | F18: Getachew Alemshet | G18: 3-90951/27927 | H18: Djb | I18: Batu(Coustc | J18: HFO | K18: 45961 | L18: 57.7473 | M18: =K18*L18 -> 2654123.7
C19: 16 | D19: 797320 | E19: 45501 | F19: Destalem Abreha | G19: 3-71435/21297 | H19: Djb | I19: Dubti(Afar) | J19: AGO | K19: 46860 | L19: 76.5447 | M19: =K19*L19 -> 3586884.6
C20: 17 | D20: 797987 | E20: 45503 | F20: Musa Adem | G20: 3-94462/28942 | H20: Djb | I20: Baeker | J20: AGO | K20: 45963 | L20: 76.5447 | M20: =K20*L20 -> 3518224
C21: 18 | D21: 798914 | E21: 45504 | F21: Kasahun Tona | G21: 3-93024/28706 | H21: Djb | I21: Metu(Elibaboura | J21: MGR | K21: 45726 | L21: 75.4077 | M21: =K21*L21 -> 3448092.5
C22: 19 | D22: 797574 | E22: 45507 | F22: Sintayehu Esheta | G22: 3-91450/27736 | H22: Djb | I22: Gonder bikil F | J22: HFO | K22: 48094 | L22: 57.7473 | M22: =K22*L22 -> 2777298.6
C23: 20 | D23: 799506 | E23: 45510 | F23: Abebe Teka | G23: 3-94456/28742 | H23: Djb | I23: Gesuba(Welaita | J23: MGR | K23: 45780 | L23: 75.4077 | M23: =K23*L23 -> 3452164.5
C24: 21 | D24: 801261 | E24: 45512 | F24: Niguse Tadese | G24: 3-93449/28749 | H24: Djb | I24: Batu(Coustc | J24: HFO | K24: 45771 | L24: 57.7473 | M24: =K24*L24 -> 2643151.7
C25: 22 | D25: 802080 | E25: 45516 | F25: Teweldebrhan Gebrezgabi | G25: 3-93601/28714 | H25: Djb | I25: Mito(Silta) | J25: MGR | K25: 45688 | L25: 75.4077 | M25: =K25*L25 -> 3445227
... C29: 26 | D29: 805662 | E29: 45525 | F29: Teshome Tesfaye | G29: 3-93434/28741 | H29: Djb | I29: Metu(Elibaboura | J29: AGO | K29: 45948 | L29: 76.5447 | M29: =K29*L29 -> 3517075.9
C30: 27 | D30: 806442 | E30: 45526 | F30: Nigus Birhane | G30: 3-89959/27428 | H30: Djb | I30: Awash (Epse | J30: AGO | K30: 47253 | M30: =K30*L30 -> 0
C31: 28 | D31: 806904 | E31: 45527 | F31: Destalem Abreha | G31: 3-71435/21297 | H31: Djb | I31: Awash (Epse | J31: AGO | K31: 46854 | M31: =K31*L31 -> 0
C32: 29 | D32: 807109 | E32: 45528 | F32: Teweldebrhan Gebrezgabi | G32: 3-93601/28714 | H32: Djb | I32: Mito(Silta) | J32: AGO | K32: 45927 | L32: 76.5447 | M32: =K32*L32 -> 3515468.4
C33: 30 | D33: 805665 | E33: 45531 | F33: Getachew Alemshet | G33: 3-90951/27927 | H33: Djb | I33: Leha(Gofa) | J33: MGR | K33: 45833 | L33: 75.4077 | M33: =K33*L33 -> 3456161.1
C34: 31 | D34: 809553 | E34: 45535 | F34: Gebrezgabher Teweidebr | G34: 3-93024/28706 | H34: Djb | I34: Gesuba(Welaita) | J34: MGR | K34: 45892 | L34: 75.4077 | M34: =K34*L34 -> 3460610.2
C35: 32 | D35: 809183 | E35: 45535 | F35: Niguse Tadese | G35: 3-93449/28749 | H35: Djb | I35: Dashen(Gonder) | J35: LHF | K35: 46344 | L35: 58.9894 | M35: =K35*L35 -> 2733804.8
C36: 33 | D36: 772808 | E36: 45538 | F36: Endalk Kibret | G36: 3-93865/29153 | H36: Djb | I36: Awash (Epse | J36: AGO | K36: 48078 | M36: =K36*L36 -> 0
C37: 34 | D37: 810608 | E37: 45539 | F37: Abebe Teka | G37: 3-94456/28742 | H37: Djb | I37: Gesuba(Welaita | J37: AGO | K37: 46058 | L37: 76.5447 | M37: =K37*L37 -> 3525495.8
C38: 35 | D38: 811070 | E38: 45543 | F38: Andualem Demoz | G38: 3-90870/27584 | H38: Djb | I38: Metu(Elibaboura | J38: MGR | K38: 45431 | L38: 75.4077 | M38: =K38*L38 -> 3425847.2
C39: 36 | D39: 812527 | E39: 45544 | F39: Tesfemariam Birhane | G39: 3-98387/29971 | H39: Djb | I39: Awash (EPSE) | J39: AGO | K39: 46869 | M39: =K39*L39 -> 0
C40: 37 | D40: 812742 | E40: 45544 | F40: Nigus Birhane | G40: 3-89959/27428 | H40: Djb | I40: Awash (EPSE) | J40: AGO | K40: 47287 | M40: =K40*L40 -> 0
C41: 38 | D41: 812861 | E41: 45544 | F41: Destalem Abreha | G41: 3-71435/21297 | H41: Djb | I41: Awash (EPSE) | J41: AGO | K41: 46858 | M41: =K41*L41 -> 0
C42: 39 | D42: 813257 | E42: 45546 | F42: Weldekidan Hailu | G42: 3-98388/29973 | H42: Djb | I42: Leha(Gofa) | J42: AGO | K42: 46608 | L42: 76.5447 | M42: =K42*L42 -> 3567595.4
C43: 40 | D43: 811543 | E43: 45548 | F43: Teweldebrhan Gebrezgabi | G43: 3-93601/28714 | H43: Djb | I43: Mito(Silta) | J43: MGR | K43: 45598 | L43: 75.4077 | M43: =K43*L43 -> 3438440.3
C44: 41 | D44: 814019 | E44: 45549 | F44: Musa Adem | G44: 3-94462/28942 | H44: Djb | I44: Baeker | J44: AGO | K44: 46001 | L44: 76.5447 | M44: =K44*L44 -> 3521132.7
C45: 42 | D45: 816619 | E45: 45555 | F45: Teshome Tesfaye | G45: 3-93434/28741 | H45: Djb | I45: Batu(Coustc | J45: HFO | K45: 46036 | L45: 57.7473 | M45: =K45*L45 -> 2658454.7
C46: 43 | D46: 818517 | E46: 45560 | F46: Gebrezgabher Teweidebr | G46: 3-93024/28706 | H46: Djb | I46: Gesuba(Welaita | J46: MGR | K46: 45957 | L46: 75.4077 | M46: =K46*L46 -> 3465511.7
...
